Workbook
Name INVEST_TOTAL: 'Investimento (CAPEX)'!$E$85

Sheet Leia-me
A1: DiscoverON — Projeção e acompanhamento financeiro (v6 · 08/09/2026)
A3: AS ABAS, NA ORDEM DE USO
A4: 1. PREMISSAS — preços, equipe (com mês de entrada), professores, sazonalidade, CAC, tabela do Simples e custos padrão. Edite só as células amarelas.
A5: 2. CUSTOS MÊS A MÊS — cada custo por período. Digite por cima para variar um mês (ex.: pró-labore só de fev, marketing maior na abertura).
A6: 3. CENÁRIOS (Pessimista / Moderado / Otimista) e SIMULADOR — projeção mês a mês.
A7: 4. CUSTOS DE IMPLANTAÇÃO (aba vermelha) — livro de lançamentos da obra/abertura, cada gasto com categoria, tipo, fornecedor e status.
A8: 5. ANÁLISE DE CUSTOS (aba roxa) — para onde o dinheiro foi: totais por categoria e tipo, matriz cruzada, pago × previsto e gráficos.
A9: 6. REALIZADO (verde) e PLANO × REAL (laranja) — o dia a dia da operação depois de aberta.
A10: 7. PAINEL DO MÊS (azul) — escolha o período e veja plano × real com alertas.
A11: 8. INVESTIMENTO (CAPEX) e RESUMO.
A13: NOVIDADES DESTA VERSÃO
A14: • MARKETING → CAC → MATRÍCULAS: nas Premissas, escolha a origem das matrículas. No modo 2, cada cenário calcula as matrículas do mês dividindo o marketing daquele período (aba 'Custos mês a mês') pelo CAC. Ex.: R$ 6.000 com CAC de R$ 200 = 30 matrículas — e todos os totais se ajustam sozinhos.
... A28: ⚠ As fórmulas estão protegidas: só as células amarelas aceitam edição. Para liberar: Revisão > Desproteger Planilha (sem senha).

Sheet Premissas
A1: PREMISSAS — edite as células amarelas
A2: Mensalidade — curso (por aluno) | B2: 280
A3: Matrícula (por aluno novo) | B3: 200
A4: Material — preço de venda (12x no cartão) | B4: 900
A5: Material — recebido à vista com antecipação | B5: 810 | E5: ~10% de taxa de antecipação do cartão.
A6: Material — custo por aluno (pago em 12x) | B6: 375
A7: Taxas do modelo
A8: Desistência mensal (% da base) | B8: 0.1
A9: Inadimplência (% da mensalidade) | B9: 0.1
A10: Comissão do vendedor por matrícula | B10: 40 | E10: Só o vendedor recebe comissão; conta a partir do mês em que ele entra.
A11: Encargos mensais sobre CLT (FGTS e provisões) | B11: 0.1 | E11: No Simples o INSS patronal já está no DAS. 13º e férias saem como desembolso próprio.
A12: Vale-transporte / benefícios por CLT (R$/mês) | B12: 200
A13: Equipe — salário, vínculo e mês de entrada | B13: Salário | C13: CLT? 1/0 | D13: Entra no período
A14: Vendedor (recebe a comissão) | B14: 2100 | C14: 1 | D14: 2 | E14: Período: 0 = Out (obras) · 1 = Nov (obras) · 2 = Dez (M1, abertura) · 3 = Jan (M2) … 17 = Mar (M16).
A15: Recepção | B15: 2000 | C15: 1 | D15: 2
A16: Estagiário | B16: 1200 | C16: 0 | D16: 2
A17: Administrador | B17: 6000 | C17: 0 | D17: 2
A18: Auxiliar de limpeza | B18: 1500 | C18: 1 | D18: 2
A19: (livre — adicione aqui) | B19: 0 | C19: 1 | D19: 2
A20: (livre) | B20: 0 | C20: 1 | D20: 2
A21: Folha com todos ativos (referência) | B21: =SUMPRODUCT($B$14:$B$20,1+$C$14:$C$20*$B$11)
A22: Professores — dimensionados pela capacidade das salas
A23: Professor CLT (salário base, cada) | B23: 1200
A24: Carga contratada (h-aula/semana) | B24: 20
A25: Coeficiente de aproveitamento da grade | B25: 0.7 | E25: A demanda concentra nos horários de pico.
A26: Salas de inglês | B26: 4
A27: Capacidade da sala de inglês | B27: 8
A28: Aulas de inglês por aluno (h/semana) | B28: 2
A29: Salas de informática | B29: 1
A30: Capacidade da sala de informática | B30: 10
A31: Aulas de informática por aluno (h/semana) | B31: 1
A32: Horas de aula por dia (9h–20h, exceto 12h–13h) | B32: 10
A33: Dias de aula por semana | B33: 5
A34: Horas-aula efetivas por professor/semana | B34: =B24*B25
A35: Custo por professor/mês (salário + encargos) | B35: =B23*(1+B11)
A36: Teto físico de alunos pelas salas | B36: =MIN(B26*B32*B33*B25/B28*B27,B29*B32*B33*B25/B31*B30)
A37: % dos alunos que fazem inglês | B37: 1
A38: % dos alunos que fazem informática | B38: 1
A40: 13º e férias — saem do caixa concentrados
A41: Pagar 13º em dezembro? (1 = sim) | B41: 1 | E41: Proporcional aos meses trabalhados no ano civil.
...

Sheet Custos mês a mês
A1: Custos por período — sobrescreva qualquer célula | B1: Out (obras) | C1: Nov (obras) | D1: Dez (M1) | E1: Jan (M2) | F1: Fev (M3) | G1: Mar (M4) | H1: Abr (M5) | I1: Mai (M6) | J1: Jun (M7) | K1: Jul (M8) | L1: Ago (M9) | M1: Set (M10) | N1: Out (M11) | O1: Nov (M12) | P1: Dez (M13) | Q1: Jan (M14) | R1: Fev (M15) | S1: Mar (M16)
A2: Aluguel do espaço | B2: 0 | C2: 0 | D2: =Premissas!$B$74 | E2: =Premissas!$B$74 | F2: =Premissas!$B$74 | G2: =Premissas!$B$74 | H2: =Premissas!$B$74 | I2: =Premissas!$B$74 | J2: =Premissas!$B$74 | K2: =Premissas!$B$74 | ... S2: =Premissas!$B$74
A3: Água | B3: 0 | C3: 0 | D3: =Premissas!$B$75 | E3: =Premissas!$B$75 | F3: =Premissas!$B$75 | G3: =Premissas!$B$75 | H3: =Premissas!$B$75 | I3: =Premissas!$B$75 | J3: =Premissas!$B$75 | K3: =Premissas!$B$75 | ... S3: =Premissas!$B$75
A4: Luz | B4: 0 | C4: 0 | D4: =Premissas!$B$76 | E4: =Premissas!$B$76 | F4: =Premissas!$B$76 | G4: =Premissas!$B$76 | H4: =Premissas!$B$76 | I4: =Premissas!$B$76 | J4: =Premissas!$B$76 | K4: =Premissas!$B$76 | ... S4: =Premissas!$B$76
A5: Telefone | B5: 0 | C5: 0 | D5: =Premissas!$B$77 | E5: =Premissas!$B$77 | F5: =Premissas!$B$77 | G5: =Premissas!$B$77 | H5: =Premissas!$B$77 | I5: =Premissas!$B$77 | J5: =Premissas!$B$77 | K5: =Premissas!$B$77 | ... S5: =Premissas!$B$77
A6: Internet | B6: 0 | C6: 0 | D6: =Premissas!$B$78 | E6: =Premissas!$B$78 | F6: =Premissas!$B$78 | G6: =Premissas!$B$78 | H6: =Premissas!$B$78 | I6: =Premissas!$B$78 | J6: =Premissas!$B$78 | K6: =Premissas!$B$78 | ... S6: =Premissas!$B$78
A7: Sistema de gestão DiscoverON | B7: 0 | C7: 0 | D7: =Premissas!$B$79 | E7: =Premissas!$B$79 | F7: =Premissas!$B$79 | G7: =Premissas!$B$79 | H7: =Premissas!$B$79 | I7: =Premissas!$B$79 | J7: =Premissas!$B$79 | K7: =Premissas!$B$79 | ... S7: =Premissas!$B$79
A8: Itens para aula | B8: 0 | C8: 0 | D8: =Premissas!$B$80 | E8: =Premissas!$B$80 | F8: =Premissas!$B$80 | G8: =Premissas!$B$80 | H8: =Premissas!$B$80 | I8: =Premissas!$B$80 | J8: =Premissas!$B$80 | K8: =Premissas!$B$80 | ... S8: =Premissas!$B$80
A9: Materiais de limpeza + higiene | B9: 0 | C9: 0 | D9: =Premissas!$B$81 | E9: =Premissas!$B$81 | F9: =Premissas!$B$81 | G9: =Premissas!$B$81 | H9: =Premissas!$B$81 | I9: =Premissas!$B$81 | J9: =Premissas!$B$81 | K9: =Premissas!$B$81 | ... S9: =Premissas!$B$81
A10: Brindes | B10: 0 | C10: 0 | D10: =Premissas!$B$82 | E10: =Premissas!$B$82 | F10: =Premissas!$B$82 | G10: =Premissas!$B$82 | H10: =Premissas!$B$82 | I10: =Premissas!$B$82 | J10: =Premissas!$B$82 | K10: =Premissas!$B$82 | ... S10: =Premissas!$B$82
A11: Marketing | B11: 0 | C11: 0 | D11: =Premissas!$B$83 | E11: =Premissas!$B$83 | F11: =Premissas!$B$83 | G11: =Premissas!$B$83 | H11: =Premissas!$B$83 | I11: =Premissas!$B$83 | J11: =Premissas!$B$83 | K11: =Premissas!$B$83 | ... S11: =Premissas!$B$83
A12: Aluguel dos computadores | B12: 0 | C12: 0 | D12: =Premissas!$B$84 | E12: =Premissas!$B$84 | F12: =Premissas!$B$84 | G12: =Premissas!$B$84 | H12: =Premissas!$B$84 | I12: =Premissas!$B$84 | J12: =Premissas!$B$84 | K12: =Premissas!$B$84 | ... S12: =Premissas!$B$84
A13: Seguro empresarial | B13: 0 | C13: 0 | D13: =Premissas!$B$85 | E13: =Premissas!$B$85 | F13: =Premissas!$B$85 | G13: =Premissas!$B$85 | H13: =Premissas!$B$85 | I13: =Premissas!$B$85 | J13: =Premissas!$B$85 | K13: =Premissas!$B$85 | ... S13: =Premissas!$B$85
A14: Taxas bancárias + gasolina | B14: 0 | C14: 0 | D14: =Premissas!$B$86 | E14: =Premissas!$B$86 | F14: =Premissas!$B$86 | G14: =Premissas!$B$86 | H14: =Premissas!$B$86 | I14: =Premissas!$B$86 | J14: =Premissas!$B$86 | K14: =Premissas!$B$86 | ... S14: =Premissas!$B$86
A15: Custos operacionais (contab., manut., licenças…) | B15: 0 | C15: 0 | D15: =Premissas!$B$87 | E15: =Premissas!$B$87 | F15: =Premissas!$B$87 | G15: =Premissas!$B$87 | H15: =Premissas!$B$87 | I15: =Premissas!$B$87 | J15: =Premissas!$B$87 | K15: =Premissas!$B$87 | ... S15: =Premissas!$B$87
A16: Pró-labore | B16: 0 | C16: 0 | D16: =Premissas!$B$88 | E16: =Premissas!$B$88 | F16: =Premissas!$B$88 | G16: =Premissas!$B$88 | H16: =Premissas!$B$88 | I16: =Premissas!$B$88 | J16: =Premissas!$B$88 | K16: =Premissas!$B$88 | ... S16: =Premissas!$B$88
A17: Total de custos do período | B17: =SUM(B2:B16) | C17: =SUM(C2:C16) | D17: =SUM(D2:D16) | E17: =SUM(E2:E16) | F17: =SUM(F2:F16) | G17: =SUM(G2:G16) | H17: =SUM(H2:H16) | I17: =SUM(I2:I16) | ... S17: =SUM(S2:S16)
A19: Out e Nov vêm zerados (obras). Do M1 em diante puxam o padrão das Premissas — digite por cima para variar o mês.
A20: A linha 11 (Marketing) alimenta o cálculo de matrículas quando o modo CAC está ligado nas Premissas.

Sheet Canais de aquisição
A1: CANAIS DE AQUISIÇÃO — de onde vem cada aluno | B1: CAC (R$) | C1: Out (obras) | D1: Nov (obras) | E1: Dez (M1) | F1: Jan (M2) | G1: Fev (M3) | H1: Mar (M4) | I1: Abr (M5) | J1: Mai (M6) | K1: Jun (M7) | L1: Jul (M8) | M1: Ago (M9) | N1: Set (M10) | O1: Out (M11) | P1: Nov (M12) | Q1: Dez (M13) | R1: Jan (M14) | S1: Fev (M15) | T1: Mar (M16)
A2: Passantes / fachada | B2: 0 | C2: 2 | D2: 11 | E2: 4 | F2: 10 | G2: 10 | H2: 6 | I2: 6 | J2: 6 | K2: 6 | L2: 10 | M2: 10 | N2: 6 | O2: 6 | P2: 10 | Q2: 10 | R2: 6 | S2: 10 | T2: 6
A3: Indicação de aluno | B3: 50 | C3: 1 | D3: 8 | E3: 3 | F3: 7 | G3: 7 | H3: 4 | I3: 4 | J3: 4 | K3: 4 | L3: 7 | M3: 7 | N3: 4 | O3: 4 | P3: 7 | Q3: 7 | R3: 4 | S3: 7 | T3: 4
A4: Tráfego pago | B4: 250 | C4: 1 | D4: 13 | E4: 5 | F4: 10 | G4: 10 | H4: 7 | I4: 7 | J4: 7 | K4: 7 | L4: 10 | M4: 10 | N4: 7 | O4: 7 | P4: 10 | Q4: 10 | R4: 7 | S4: 10 | T4: 7
A5: Redes sociais (orgânico) | B5: 0 | C5: 0 | D5: 1 | E5: 1 | F5: 1 | G5: 1 | H5: 1 | I5: 1 | J5: 1 | K5: 1 | L5: 1 | M5: 1 | N5: 1 | O5: 1 | P5: 1 | Q5: 1 | R5: 1 | S5: 1 | T5: 1
A6: Parcerias / escolas | B6: 80 | C6: 0 | D6: 1 | E6: 0 | F6: 1 | G6: 1 | H6: 1 | I6: 1 | J6: 1 | K6: 1 | L6: 1 | M6: 1 | N6: 1 | O6: 1 | P6: 1 | Q6: 1 | R6: 1 | S6: 1 | T6: 1
A7: Eventos / panfletagem | B7: 120 | C7: 0 | D7: 1 | E7: 0 | F7: 1 | G7: 1 | H7: 1 | I7: 1 | J7: 1 | K7: 1 | L7: 1 | M7: 1 | N7: 1 | O7: 1 | P7: 1 | Q7: 1 | R7: 1 | S7: 1 | T7: 1
A8: Outros | B8: 0 | C8: 0 | D8: 0 | E8: 0 | F8: 0 | G8: 0 | H8: 0 | I8: 0 | J8: 0 | K8: 0 | L8: 0 | M8: 0 | N8: 0 | O8: 0 | P8: 0 | Q8: 0 | R8: 0 | S8: 0 | T8: 0
A9: Total de matrículas do mês | C9: =SUM(C2:C8) | D9: =SUM(D2:D8) | E9: =SUM(E2:E8) | F9: =SUM(F2:F8) | G9: =SUM(G2:G8) | H9: =SUM(H2:H8) | I9: =SUM(I2:I8) | J9: =SUM(J2:J8) | ... T9: =SUM(T2:T8)
A10: Custo de aquisição do mês | C10: =SUMPRODUCT(C$2:C$8,$B$2:$B$8) | D10: =SUMPRODUCT(D$2:D$8,$B$2:$B$8) | E10: =SUMPRODUCT(E$2:E$8,$B$2:$B$8) | F10: =SUMPRODUCT(F$2:F$8,$B$2:$B$8) | G10: =SUMPRODUCT(G$2:G$8,$B$2:$B$8) | H10: =SUMPRODUCT(H$2:H$8,$B$2:$B$8) | I10: =SUMPRODUCT(I$2:I$8,$B$2:$B$8) | J10: =SUMPRODUCT(J$2:J$8,$B$2:$B$8) | ... T10: =SUMPRODUCT(T$2:T$8,$B$2:$B$8)
A11: CAC médio do mês | C11: =IF(C9=0,0,C10/C9) | D11: =IF(D9=0,0,D10/D9) | E11: =IF(E9=0,0,E10/E9) | F11: =IF(F9=0,0,F10/F9) | G11: =IF(G9=0,0,G10/G9) | H11: =IF(H9=0,0,H10/H9) | I11: =IF(I9=0,0,I10/I9) | J11: =IF(J9=0,0,J10/J9) | ... T11: =IF(T9=0,0,T10/T9)
A13: RETORNO POR CANAL (todo o horizonte)
A14: Canal | B14: Alunos | C14: % das matrículas | D14: Investido | E14: CAC realizado | F14: Alunos por R$ 1.000
A15: =A2 | B15: =SUM(C2:T2) | C15: =IF(SUM($B$15:$B$21)=0,0,B15/SUM($B$15:$B$21)) | D15: =B15*$B$2 | E15: =IF(B15=0,0,D15/B15) | F15: =IF(D15=0,"— (orgânico)",B15/(D15/1000))
A16: =A3 | B16: =SUM(C3:T3) | C16: =IF(SUM($B$15:$B$21)=0,0,B16/SUM($B$15:$B$21)) | D16: =B16*$B$3 | E16: =IF(B16=0,0,D16/B16) | F16: =IF(D16=0,"— (orgânico)",B16/(D16/1000))
A17: =A4 | B17: =SUM(C4:T4) | C17: =IF(SUM($B$15:$B$21)=0,0,B17/SUM($B$15:$B$21)) | D17: =B17*$B$4 | E17: =IF(B17=0,0,D17/B17) | F17: =IF(D17=0,"— (orgânico)",B17/(D17/1000))
A18: =A5 | B18: =SUM(C5:T5) | C18: =IF(SUM($B$15:$B$21)=0,0,B18/SUM($B$15:$B$21)) | D18: =B18*$B$5 | E18: =IF(B18=0,0,D18/B18) | F18: =IF(D18=0,"— (orgânico)",B18/(D18/1000))
A19: =A6 | B19: =SUM(C6:T6) | C19: =IF(SUM($B$15:$B$21)=0,0,B19/SUM($B$15:$B$21)) | D19: =B19*$B$6 | E19: =IF(B19=0,0,D19/B19) | F19: =IF(D19=0,"— (orgânico)",B19/(D19/1000))
A20: =A7 | B20: =SUM(C7:T7) | C20: =IF(SUM($B$15:$B$21)=0,0,B20/SUM($B$15:$B$21)) | D20: =B20*$B$7 | E20: =IF(B20=0,0,D20/B20) | F20: =IF(D20=0,"— (orgânico)",B20/(D20/1000))
A21: =A8 | B21: =SUM(C8:T8) | C21: =IF(SUM($B$15:$B$21)=0,0,B21/SUM($B$15:$B$21)) | D21: =B21*$B$8 | E21: =IF(B21=0,0,D21/B21) | F21: =IF(D21=0,"— (orgânico)",B21/(D21/1000))
A22: Só canais pagos (CAC > 0) | B22: =SUMIF($B$2:$B$8,">0",$B$15:$B$21) | D22: =SUMIF($B$2:$B$8,">0",$D$15:$D$21) | E22: =IF(B22=0,0,D22/B22) | F22: =IF(D22=0,0,B22/(D22/1000))
A24: Quantos alunos cada R$ 1.000 traz: compare o tráfego pago com indicação e parcerias antes de decidir onde botar a verba.
A26: Lance quantos alunos vieram de cada canal em cada mês. O CAC de cada canal (coluna B) multiplica a quantidade e vira a linha 'Aquisição de alunos' nos cenários.
A27: Canais orgânicos (passantes, indicação, redes) podem ter CAC 0 ou só o bônus de indicação. Tráfego pago é onde o dinheiro sai de fato.
A28: Para as matrículas virem daqui, coloque 3 em 'Origem das matrículas' nas Premissas. Esta aba vale para os 3 cenários.

Sheet Cenário Pessimista
A1: Cenário Pessimista | B1: Out (obras) | C1: Nov (obras) | D1: Dez (M1) | E1: Jan (M2) | F1: Fev (M3) | G1: Mar (M4) | H1: Abr (M5) | I1: Mai (M6) | J1: Jun (M7) | K1: Jul (M8) | L1: Ago (M9) | M1: Set (M10) | N1: Out (M11) | O1: Nov (M12) | P1: Dez (M13) | Q1: Jan (M14) | R1: Fev (M15) | S1: Mar (M16)
A2: Período (0 = out) | B2: 0 | C2: 1 | D2: 2 | E2: 3 | F2: 4 | G2: 5 | H2: 6 | I2: 7 | J2: 8 | K2: 9 | L2: 10 | M2: 11 | N2: 12 | O2: 13 | P2: 14 | Q2: 15 | R2: 16 | S2: 17
A3: Matrículas — entrada manual ✏️ editável | B3: 2 | C3: 20 | D3: 10 | E3: 20 | F3: 25 | G3: 15 | H3: 15 | I3: 15 | J3: 15 | K3: 20 | L3: 20 | M3: 15 | N3: 15 | O3: 20 | P3: 20 | Q3: 15 | R3: 20 | S3: 15 | U3: Break-even (alunos):
A4: Matrículas no período (vale para o cálculo) | B4: =IF(Premissas!$B$59=3,'Canais de aquisição'!C$9,IF(Premissas!$B$59=2,ROUND('Custos mês a mês'!B$11/MAX(Premissas!$B$60,1),0),B3)) | C4: =IF(Premissas!$B$59=3,'Canais de aquisição'!D$9,IF(Premissas!$B$59=2,ROUND('Custos mês a mês'!C$11/MAX(Premissas!$B$60,1),0),C3)) | D4: =IF(Premissas!$B$59=3,'Canais de aquisição'!E$9,IF(Premissas!$B$59=2,ROUND('Custos mês a mês'!D$11/MAX(Premissas!$B$60,1),0),D3)) | E4: =IF(Premissas!$B$59=3,'Canais de aquisição'!F$9,IF(Premissas!$B$59=2,ROUND('Custos mês a mês'!E$11/MAX(Premissas!$B$60,1),0),E3)) | F4: =IF(Premissas!$B$59=3,'Canais de aquisição'!G$9,IF(Premissas!$B$59=2,ROUND('Custos mês a mês'!F$11/MAX(Premissas!$B$60,1),0),F3)) | G4: =IF(Premissas!$B$59=3,'Canais de aquisição'!H$9,IF(Premissas!$B$59=2,ROUND('Custos mês a mês'!G$11/MAX(Premissas!$B$60,1),0),G3)) | H4: =IF(Premissas!$B$59=3,'Canais de aquisição'!I$9,IF(Premissas!$B$59=2,ROUND('Custos mês a mês'!H$11/MAX(Premissas!$B$60,1),0),H3)) | I4: =IF(Premissas!$B$59=3,'Canais de aquisição'!J$9,IF(Premissas!$B$59=2,ROUND('Custos mês a mês'!I$11/MAX(Premissas!$B$60,1),0),I3)) | ... S4: =IF(Premissas!$B$59=3,'Canais de aquisição'!T$9,IF(Premissas!$B$59=2,ROUND('Custos mês a mês'!S$11/MAX(Premissas!$B$60,1),0),S3)) | U4: =Premissas!$B$90
A5: CAC realizado (marketing + canais ÷ matrículas) | B5: =IF(B4=0,0,('Custos mês a mês'!B$11+'Canais de aquisição'!C$10)/B4) | C5: =IF(C4=0,0,('Custos mês a mês'!C$11+'Canais de aquisição'!D$10)/C4) | D5: =IF(D4=0,0,('Custos mês a mês'!D$11+'Canais de aquisição'!E$10)/D4) | E5: =IF(E4=0,0,('Custos mês a mês'!E$11+'Canais de aquisição'!F$10)/E4) | F5: =IF(F4=0,0,('Custos mês a mês'!F$11+'Canais de aquisição'!G$10)/F4) | G5: =IF(G4=0,0,('Custos mês a mês'!G$11+'Canais de aquisição'!H$10)/G4) | H5: =IF(H4=0,0,('Custos mês a mês'!H$11+'Canais de aquisição'!I$10)/H4) | I5: =IF(I4=0,0,('Custos mês a mês'!I$11+'Canais de aquisição'!J$10)/I4) | ... S5: =IF(S4=0,0,('Custos mês a mês'!S$11+'Canais de aquisição'!T$10)/S4)
A6: Desistências no mês | B6: 0 | C6: =B7*Premissas!$B$8*Premissas!$B$55 | D6: =C7*Premissas!$B$8*Premissas!$B$56 | E6: =D7*Premissas!$B$8*Premissas!$B$45 | F6: =E7*Premissas!$B$8*Premissas!$B$46 | G6: =F7*Premissas!$B$8*Premissas!$B$47 | H6: =G7*Premissas!$B$8*Premissas!$B$48 | I6: =H7*Premissas!$B$8*Premissas!$B$49 | J6: =I7*Premissas!$B$8*Premissas!$B$50 | K6: =J7*Premissas!$B$8*Premissas!$B$51 | L6: =K7*Premissas!$B$8*Premissas!$B$52 | M6: =L7*Premissas!$B$8*Premissas!$B$53 | N6: =M7*Premissas!$B$8*Premissas!$B$54 | O6: =N7*Premissas!$B$8*Premissas!$B$55 | P6: =O7*Premissas!$B$8*Premissas!$B$56 | Q6: =P7*Premissas!$B$8*Premissas!$B$45 | R6: =Q7*Premissas!$B$8*Premissas!$B$46 | S6: =R7*Premissas!$B$8*Premissas!$B$47 | U6: 🟢 VERDE FORTE = mês do BREAK-EVEN
A7: Total de alunos | B7: =B4 | C7: =B7-C6+C4 | D7: =C7-D6+D4 | E7: =D7-E6+E4 | F7: =E7-F6+F4 | G7: =F7-G6+G4 | H7: =G7-H6+H4 | I7: =H7-I6+I4 | J7: =I7-J6+J4 | ... S7: =R7-S6+S4 | U7: 🟦 AZUL = mês do PAYBACK
A8: Professores necessários | B8: 0 | C8: 0 | D8: =CEILING(CEILING(D7*Premissas!$B$37/Premissas!$B$27,1)*Premissas!$B$28/Premissas!$B$34,1)+CEILING(CEILING(D7*Premissas!$B$38/Premissas!$B$30,1)*Premissas!$B$31/Premissas!$B$34,1) | E8: =CEILING(CEILING(E7*Premissas!$B$37/Premissas!$B$27,1)*Premissas!$B$28/Premissas!$B$34,1)+CEILING(CEILING(E7*Premissas!$B$38/Premissas!$B$30,1)*Premissas!$B$31/Premissas!$B$34,1) | F8: =CEILING(CEILING(F7*Premissas!$B$37/Premissas!$B$27,1)*Premissas!$B$28/Premissas!$B$34,1)+CEILING(CEILING(F7*Premissas!$B$38/Premissas!$B$30,1)*Premissas!$B$31/Premissas!$B$34,1) | G8: =CEILING(CEILING(G7*Premissas!$B$37/Premissas!$B$27,1)*Premissas!$B$28/Premissas!$B$34,1)+CEILING(CEILING(G7*Premissas!$B$38/Premissas!$B$30,1)*Premissas!$B$31/Premissas!$B$34,1) | H8: =CEILING(CEILING(H7*Premissas!$B$37/Premissas!$B$27,1)*Premissas!$B$28/Premissas!$B$34,1)+CEILING(CEILING(H7*Premissas!$B$38/Premissas!$B$30,1)*Premissas!$B$31/Premissas!$B$34,1) | I8: =CEILING(CEILING(I7*Premissas!$B$37/Premissas!$B$27,1)*Premissas!$B$28/Premissas!$B$34,1)+CEILING(CEILING(I7*Premissas!$B$38/Premissas!$B$30,1)*Premissas!$B$31/Premissas!$B$34,1) | J8: =CEILING(CEILING(J7*Premissas!$B$37/Premissas!$B$27,1)*Premissas!$B$28/Premissas!$B$34,1)+CEILING(CEILING(J7*Premissas!$B$38/Premissas!$B$30,1)*Premissas!$B$31/Premissas!$B$34,1) | K8: =CEILING(CEILING(K7*Premissas!$B$37/Premissas!$B$27,1)*Premissas!$B$28/Premissas!$B$34,1)+CEILING(CEILING(K7*Premissas!$B$38/Premissas!$B$30,1)*Premissas!$B$31/Premissas!$B$34,1) | ... S8: =CEILING(CEILING(S7*Premissas!$B$37/Premissas!$B$27,1)*Premissas!$B$28/Premissas!$B$34,1)+CEILING(CEILING(S7*Premissas!$B$38/Premissas!$B$30,1)*Premissas!$B$31/Premissas!$B$34,1) | U8: 🟩 verde claro = meses já positivos
A9: Ocupação das salas (100% = grade cheia) | B9: 0 | C9: 0 | D9: =MAX(CEILING(D7*Premissas!$B$37/Premissas!$B$27,1)*Premissas!$B$28/(Premissas!$B$26*Premissas!$B$32*Premissas!$B$33*Premissas!$B$25),CEILING(D7*Premissas!$B$38/Premissas!$B$30,1)*Premissas!$B$31/(Premissas!$B$29*Premissas!$B$32*Premissas!$B$33*Premissas!$B$25)) | E9: =MAX(CEILING(E7*Premissas!$B$37/Premissas!$B$27,1)*Premissas!$B$28/(Premissas!$B$26*Premissas!$B$32*Premissas!$B$33*Premissas!$B$25),CEILING(E7*Premissas!$B$38/Premissas!$B$30,1)*Premissas!$B$31/(Premissas!$B$29*Premissas!$B$32*Premissas!$B$33*Premissas!$B$25)) | F9: =MAX(CEILING(F7*Premissas!$B$37/Premissas!$B$27,1)*Premissas!$B$28/(Premissas!$B$26*Premissas!$B$32*Premissas!$B$33*Premissas!$B$25),CEILING(F7*Premissas!$B$38/Premissas!$B$30,1)*Premissas!$B$31/(Premissas!$B$29*Premissas!$B$32*Premissas!$B$33*Premissas!$B$25)) | G9: =MAX(CEILING(G7*Premissas!$B$37/Premissas!$B$27,1)*Premissas!$B$28/(Premissas!$B$26*Premissas!$B$32*Premissas!$B$33*Premissas!$B$25),CEILING(G7*Premissas!$B$38/Premissas!$B$30,1)*Premissas!$B$31/(Premissas!$B$29*Premissas!$B$32*Premissas!$B$33*Premissas!$B$25)) | H9: =MAX(CEILING(H7*Premissas!$B$37/Premissas!$B$27,1)*Premissas!$B$28/(Premissas!$B$26*Premissas!$B$32*Premissas!$B$33*Premissas!$B$25),CEILING(H7*Premissas!$B$38/Premissas!$B$30,1)*Premissas!$B$31/(Premissas!$B$29*Premissas!$B$32*Premissas!$B$33*Premissas!$B$25)) | I9: =MAX(CEILING(I7*Premissas!$B$37/Premissas!$B$27,1)*Premissas!$B$28/(Premissas!$B$26*Premissas!$B$32*Premissas!$B$33*Premissas!$B$25),CEILING(I7*Premissas!$B$38/Premissas!$B$30,1)*Premissas!$B$31/(Premissas!$B$29*Premissas!$B$32*Premissas!$B$33*Premissas!$B$25)) | J9: =MAX(CEILING(J7*Premissas!$B$37/Premissas!$B$27,1)*Premissas!$B$28/(Premissas!$B$26*Premissas!$B$32*Premissas!$B$33*Premissas!$B$25),CEILING(J7*Premissas!$B$38/Premissas!$B$30,1)*Premissas!$B$31/(Premissas!$B$29*Premissas!$B$32*Premissas!$B$33*Premissas!$B$25)) | K9: =MAX(CEILING(K7*Premissas!$B$37/Premissas!$B$27,1)*Premissas!$B$28/(Premissas!$B$26*Premissas!$B$32*Premissas!$B$33*Premissas!$B$25),CEILING(K7*Premissas!$B$38/Premissas!$B$30,1)*Premissas!$B$31/(Premissas!$B$29*Premissas!$B$32*Premissas!$B$33*Premissas!$B$25)) | ... S9: =MAX(CEILING(S7*Premissas!$B$37/Premissas!$B$27,1)*Premissas!$B$28/(Premissas!$B$26*Premissas!$B$32*Premissas!$B$33*Premissas!$B$25),CEILING(S7*Premissas!$B$38/Premissas!$B$30,1)*Premissas!$B$31/(Premissas!$B$29*Premissas!$B$32*Premissas!$B$33*Premissas!$B$25))
A11: RECEITA RECEBIDA (caixa)
A12: Matrícula | B12: =B4*Premissas!$B$3 | C12: =C4*Premissas!$B$3 | D12: =D4*Premissas!$B$3 | E12: =E4*Premissas!$B$3 | F12: =F4*Premissas!$B$3 | G12: =G4*Premissas!$B$3 | H12: =H4*Premissas!$B$3 | I12: =I4*Premissas!$B$3 | ... S12: =S4*Premissas!$B$3
A13: Mensalidade recebida (líq. de inadimplência) | B13: 0 | C13: 0 | D13: =C7*Premissas!$B$2*(1-Premissas!$B$9) | E13: =D7*Premissas!$B$2*(1-Premissas!$B$9) | F13: =E7*Premissas!$B$2*(1-Premissas!$B$9) | G13: =F7*Premissas!$B$2*(1-Premissas!$B$9) | H13: =G7*Premissas!$B$2*(1-Premissas!$B$9) | I13: =H7*Premissas!$B$2*(1-Premissas!$B$9) | J13: =I7*Premissas!$B$2*(1-Premissas!$B$9) | K13: =J7*Premissas!$B$2*(1-Premissas!$B$9) | ... S13: =R7*Premissas!$B$2*(1-Premissas!$B$9)
A14: Material antecipado no cartão | B14: =B4*Premissas!$B$5 | C14: =C4*Premissas!$B$5 | D14: =D4*Premissas!$B$5 | E14: =E4*Premissas!$B$5 | F14: =F4*Premissas!$B$5 | G14: =G4*Premissas!$B$5 | H14: =H4*Premissas!$B$5 | I14: =I4*Premissas!$B$5 | ... S14: =S4*Premissas!$B$5
A15: Receita recebida | B15: =SUM(B12:B14) | C15: =SUM(C12:C14) | D15: =SUM(D12:D14) | E15: =SUM(E12:E14) | F15: =SUM(F12:F14) | G15: =SUM(G12:G14) | H15: =SUM(H12:H14) | I15: =SUM(I12:I14) | ... S15: =SUM(S12:S14)
A17: BASE DO SIMPLES NACIONAL
A18: Faturamento do mês (nota emitida) | B18: =B4*Premissas!$B$3+B4*Premissas!$B$4 | C18: =C4*Premissas!$B$3+C4*Premissas!$B$4 | D18: =D4*Premissas!$B$3+C7*Premissas!$B$2+D4*Premissas!$B$4 | E18: =E4*Premissas!$B$3+D7*Premissas!$B$2+E4*Premissas!$B$4 | F18: =F4*Premissas!$B$3+E7*Premissas!$B$2+F4*Premissas!$B$4 | G18: =G4*Premissas!$B$3+F7*Premissas!$B$2+G4*Premissas!$B$4 | H18: =H4*Premissas!$B$3+G7*Premissas!$B$2+H4*Premissas!$B$4 | I18: =I4*Premissas!$B$3+H7*Premissas!$B$2+I4*Premissas!$B$4 | J18: =J4*Premissas!$B$3+I7*Premissas!$B$2+J4*Premissas!$B$4 | K18: =K4*Premissas!$B$3+J7*Premissas!$B$2+K4*Premissas!$B$4 | ... S18: =S4*Premissas!$B$3+R7*Premissas!$B$2+S4*Premissas!$B$4
A19: RBT12 proporcionalizado | B19: =SUM($B$18:B18)/1*12 | C19: =SUM($B$18:C18)/2*12 | D19: =SUM($B$18:D18)/3*12 | E19: =SUM($B$18:E18)/4*12 | F19: =SUM($B$18:F18)/5*12 | G19: =SUM($B$18:G18)/6*12 | H19: =SUM($B$18:H18)/7*12 | I19: =SUM($B$18:I18)/8*12 | J19: =SUM($B$18:J18)/9*12 | K19: =SUM($B$18:K18)/10*12 | L19: =SUM($B$18:L18)/11*12 | M19: =SUM(B18:M18) | N19: =SUM(C18:N18) | O19: =SUM(D18:O18) | P19: =SUM(E18:P18) | Q19: =SUM(F18:Q18) | R19: =SUM(G18:R18) | S19: =SUM(H18:S18)
A20: Alíquota efetiva do Simples | B20: =IF(B19=0,Premissas!$C$66,IF(B19<=Premissas!$B$66,(B19*Premissas!$C$66-Premissas!$D$66)/B19,IF(B19<=Premissas!$B$67,(B19*Premissas!$C$67-Premissas!$D$67)/B19,IF(B19<=Premissas!$B$68,(B19*Premissas!$C$68-Premissas!$D$68)/B19,IF(B19<=Premissas!$B$69,(B19*Premissas!$C$69-Premissas!$D$69)/B19,IF(B19<=Premissas!$B$70,(B19*Premissas!$C$70-Premissas!$D$70)/B19,(B19*Premissas!$C$71-Premissas!$D$71)/B19)))))) | C20: =IF(C19=0,Premissas!$C$66,IF(C19<=Premissas!$B$66,(C19*Premissas!$C$66-Premissas!$D$66)/C19,IF(C19<=Premissas!$B$67,(C19*Premissas!$C$67-Premissas!$D$67)/C19,IF(C19<=Premissas!$B$68,(C19*Premissas!$C$68-Premissas!$D$68)/C19,IF(C19<=Premissas!$B$69,(C19*Premissas!$C$69-Premissas!$D$69)/C19,IF(C19<=Premissas!$B$70,(C19*Premissas!$C$70-Premissas!$D$70)/C19,(C19*Premissas!$C$71-Premissas!$D$71)/C19)))))) | D20: =IF(D19=0,Premissas!$C$66,IF(D19<=Premissas!$B$66,(D19*Premissas!$C$66-Premissas!$D$66)/D19,IF(D19<=Premissas!$B$67,(D19*Premissas!$C$67-Premissas!$D$67)/D19,IF(D19<=Premissas!$B$68,(D19*Premissas!$C$68-Premissas!$D$68)/D19,IF(D19<=Premissas!$B$69,(D19*Premissas!$C$69-Premissas!$D$69)/D19,IF(D19<=Premissas!$B$70,(D19*Premissas!$C$70-Premissas!$D$70)/D19,(D19*Premissas!$C$71-Premissas!$D$71)/D19)))))) | E20: =IF(E19=0,Premissas!$C$66,IF(E19<=Premissas!$B$66,(E19*Premissas!$C$66-Premissas!$D$66)/E19,IF(E19<=Premissas!$B$67,(E19*Premissas!$C$67-Premissas!$D$67)/E19,IF(E19<=Premissas!$B$68,(E19*Premissas!$C$68-Premissas!$D$68)/E19,IF(E19<=Premissas!$B$69,(E19*Premissas!$C$69-Premissas!$D$69)/E19,IF(E19<=Premissas!$B$70,(E19*Premissas!$C$70-Premissas!$D$70)/E19,(E19*Premissas!$C$71-Premissas!$D$71)/E19)))))) | F20: =IF(F19=0,Premissas!$C$66,IF(F19<=Premissas!$B$66,(F19*Premissas!$C$66-Premissas!$D$66)/F19,IF(F19<=Premissas!$B$67,(F19*Premissas!$C$67-Premissas!$D$67)/F19,IF(F19<=Premissas!$B$68,(F19*Premissas!$C$68-Premissas!$D$68)/F19,IF(F19<=Premissas!$B$69,(F19*Premissas!$C$69-Premissas!$D$69)/F19,IF(F19<=Premissas!$B$70,(F19*Premissas!$C$70-Premissas!$D$70)/F19,(F19*Premissas!$C$71-Premissas!$D$71)/F19)))))) | G20: =IF(G19=0,Premissas!$C$66,IF(G19<=Premissas!$B$66,(G19*Premissas!$C$66-Premissas!$D$66)/G19,IF(G19<=Premissas!$B$67,(G19*Premissas!$C$67-Premissas!$D$67)/G19,IF(G19<=Premissas!$B$68,(G19*Premissas!$C$68-Premissas!$D$68)/G19,IF(G19<=Premissas!$B$69,(G19*Premissas!$C$69-Premissas!$D$69)/G19,IF(G19<=Premissas!$B$70,(G19*Premissas!$C$70-Premissas!$D$70)/G19,(G19*Premissas!$C$71-Premissas!$D$71)/G19)))))) | H20: =IF(H19=0,Premissas!$C$66,IF(H19<=Premissas!$B$66,(H19*Premissas!$C$66-Premissas!$D$66)/H19,IF(H19<=Premissas!$B$67,(H19*Premissas!$C$67-Premissas!$D$67)/H19,IF(H19<=Premissas!$B$68,(H19*Premissas!$C$68-Premissas!$D$68)/H19,IF(H19<=Premissas!$B$69,(H19*Premissas!$C$69-Premissas!$D$69)/H19,IF(H19<=Premissas!$B$70,(H19*Premissas!$C$70-Premissas!$D$70)/H19,(H19*Premissas!$C$71-Premissas!$D$71)/H19)))))) | I20: =IF(I19=0,Premissas!$C$66,IF(I19<=Premissas!$B$66,(I19*Premissas!$C$66-Premissas!$D$66)/I19,IF(I19<=Premissas!$B$67,(I19*Premissas!$C$67-Premissas!$D$67)/I19,IF(I19<=Premissas!$B$68,(I19*Premissas!$C$68-Premissas!$D$68)/I19,IF(I19<=Premissas!$B$69,(I19*Premissas!$C$69-Premissas!$D$69)/I19,IF(I19<=Premissas!$B$70,(I19*Premissas!$C$70-Premissas!$D$70)/I19,(I19*Premissas!$C$71-Premissas!$D$71)/I19)))))) | ... S20: =IF(S19=0,Premissas!$C$66,IF(S19<=Premissas!$B$66,(S19*Premissas!$C$66-Premissas!$D$66)/S19,IF(S19<=Premissas!$B$67,(S19*Premissas!$C$67-Premissas!$D$67)/S19,IF(S19<=Premissas!$B$68,(S19*Premissas!$C$68-Premissas!$D$68)/S19,IF(S19<=Premissas!$B$69,(S19*Premissas!$C$69-Premissas!$D$69)/S19,IF(S19<=Premissas!$B$70,(S19*Premissas!$C$70-Premissas!$D$70)/S19,(S19*Premissas!$C$71-Premissas!$D$71)/S19))))))
A22: DESPESAS
A23: Impostos (Simples progressivo) | B23: =B18*B20 | C23: =C18*C20 | D23: =D18*D20 | E23: =E18*E20 | F23: =F18*F20 | G23: =G18*G20 | H23: =H18*H20 | I23: =I18*I20 | ... S23: =S18*S20
A24: Material — parcelas 12x | B24: 0 | C24: 0 | D24: =SUM($B$4:D4)*Premissas!$B$6/12 | E24: =SUM($B$4:E4)*Premissas!$B$6/12 | F24: =SUM($B$4:F4)*Premissas!$B$6/12 | G24: =SUM($B$4:G4)*Premissas!$B$6/12 | H24: =SUM($B$4:H4)*Premissas!$B$6/12 | I24: =SUM($B$4:I4)*Premissas!$B$6/12 | J24: =SUM($B$4:J4)*Premissas!$B$6/12 | K24: =SUM($B$4:K4)*Premissas!$B$6/12 | ... O24: =SUM($B$4:O4)*Premissas!$B$6/12 | P24: =SUM(E4:P4)*Premissas!$B$6/12 | Q24: =SUM(F4:Q4)*Premissas!$B$6/12 | R24: =SUM(G4:R4)*Premissas!$B$6/12 | S24: =SUM(H4:S4)*Premissas!$B$6/12
A25: Comissão do vendedor | B25: =IF(B2>=Premissas!$D$14,B4*Premissas!$B$10*(1+Premissas!$B$11),0) | C25: =IF(C2>=Premissas!$D$14,C4*Premissas!$B$10*(1+Premissas!$B$11),0) | D25: =IF(D2>=Premissas!$D$14,D4*Premissas!$B$10*(1+Premissas!$B$11),0) | E25: =IF(E2>=Premissas!$D$14,E4*Premissas!$B$10*(1+Premissas!$B$11),0) | F25: =IF(F2>=Premissas!$D$14,F4*Premissas!$B$10*(1+Premissas!$B$11),0) | G25: =IF(G2>=Premissas!$D$14,G4*Premissas!$B$10*(1+Premissas!$B$11),0) | H25: =IF(H2>=Premissas!$D$14,H4*Premissas!$B$10*(1+Premissas!$B$11),0) | I25: =IF(I2>=Premissas!$D$14,I4*Premissas!$B$10*(1+Premissas!$B$11),0) | ... S25: =IF(S2>=Premissas!$D$14,S4*Premissas!$B$10*(1+Premissas!$B$11),0)
A26: Aquisição de alunos (custo dos canais) | B26: ='Canais de aquisição'!C$10 | C26: ='Canais de aquisição'!D$10 | D26: ='Canais de aquisição'!E$10 | E26: ='Canais de aquisição'!F$10 | F26: ='Canais de aquisição'!G$10 | G26: ='Canais de aquisição'!H$10 | H26: ='Canais de aquisição'!I$10 | I26: ='Canais de aquisição'!J$10 | ... S26: ='Canais de aquisição'!T$10
A27: Folha + encargos mensais (só quem já entrou) | B27: =SUMPRODUCT((Premissas!$D$14:$D$20<=B2)*Premissas!$B$14:$B$20*(1+Premissas!$C$14:$C$20*Premissas!$B$11)) | C27: =SUMPRODUCT((Premissas!$D$14:$D$20<=C2)*Premissas!$B$14:$B$20*(1+Premissas!$C$14:$C$20*Premissas!$B$11)) | D27: =SUMPRODUCT((Premissas!$D$14:$D$20<=D2)*Premissas!$B$14:$B$20*(1+Premissas!$C$14:$C$20*Premissas!$B$11)) | E27: =SUMPRODUCT((Premissas!$D$14:$D$20<=E2)*Premissas!$B$14:$B$20*(1+Premissas!$C$14:$C$20*Premissas!$B$11)) | F27: =SUMPRODUCT((Premissas!$D$14:$D$20<=F2)*Premissas!$B$14:$B$20*(1+Premissas!$C$14:$C$20*Premissas!$B$11)) | G27: =SUMPRODUCT((Premissas!$D$14:$D$20<=G2)*Premissas!$B$14:$B$20*(1+Premissas!$C$14:$C$20*Premissas!$B$11)) | H27: =SUMPRODUCT((Premissas!$D$14:$D$20<=H2)*Premissas!$B$14:$B$20*(1+Premissas!$C$14:$C$20*Premissas!$B$11)) | I27: =SUMPRODUCT((Premissas!$D$14:$D$20<=I2)*Premissas!$B$14:$B$20*(1+Premissas!$C$14:$C$20*Premissas!$B$11)) | ... S27: =SUMPRODUCT((Premissas!$D$14:$D$20<=S2)*Premissas!$B$14:$B$20*(1+Premissas!$C$14:$C$20*Premissas!$B$11))
A28: Vale-transporte / benefícios | B28: =SUMPRODUCT((Premissas!$D$14:$D$20<=B2)*Premissas!$C$14:$C$20*(Premissas!$B$14:$B$20>0))*Premissas!$B$12 | C28: =SUMPRODUCT((Premissas!$D$14:$D$20<=C2)*Premissas!$C$14:$C$20*(Premissas!$B$14:$B$20>0))*Premissas!$B$12 | D28: =SUMPRODUCT((Premissas!$D$14:$D$20<=D2)*Premissas!$C$14:$C$20*(Premissas!$B$14:$B$20>0))*Premissas!$B$12 | E28: =SUMPRODUCT((Premissas!$D$14:$D$20<=E2)*Premissas!$C$14:$C$20*(Premissas!$B$14:$B$20>0))*Premissas!$B$12 | F28: =SUMPRODUCT((Premissas!$D$14:$D$20<=F2)*Premissas!$C$14:$C$20*(Premissas!$B$14:$B$20>0))*Premissas!$B$12 | G28: =SUMPRODUCT((Premissas!$D$14:$D$20<=G2)*Premissas!$C$14:$C$20*(Premissas!$B$14:$B$20>0))*Premissas!$B$12 | H28: =SUMPRODUCT((Premissas!$D$14:$D$20<=H2)*Premissas!$C$14:$C$20*(Premissas!$B$14:$B$20>0))*Premissas!$B$12 | I28: =SUMPRODUCT((Premissas!$D$14:$D$20<=I2)*Premissas!$C$14:$C$20*(Premissas!$B$14:$B$20>0))*Premissas!$B$12 | ... S28: =SUMPRODUCT((Premissas!$D$14:$D$20<=S2)*Premissas!$C$14:$C$20*(Premissas!$B$14:$B$20>0))*Premissas!$B$12
A29: 13º e férias (desembolso) | B29: 0 | C29: 0 | D29: =Premissas!$B$41*SUMPRODUCT((Premissas!$D$14:$D$20<=2)*Premissas!$C$14:$C$20*Premissas!$B$14:$B$20*(2-((Premissas!$D$14:$D$20>0)*Premissas!$D$14:$D$20+(Premissas!$D$14:$D$20<=0)*0)+1)/12)+0 | E29: 0 | F29: 0 | G29: 0 | H29: 0 | I29: 0 | J29: 0 | K29: 0 | L29: 0 | M29: 0 | N29: =0+Premissas!$B$42*SUMPRODUCT((Premissas!$D$14:$D$20=0)*Premissas!$C$14:$C$20*Premissas!$B$14:$B$20)*4/3 | O29: =0+Premissas!$B$42*SUMPRODUCT((Premissas!$D$14:$D$20=1)*Premissas!$C$14:$C$20*Premissas!$B$14:$B$20)*4/3 | P29: =Premissas!$B$41*SUMPRODUCT((Premissas!$D$14:$D$20<=14)*Premissas!$C$14:$C$20*Premissas!$B$14:$B$20*(14-((Premissas!$D$14:$D$20>3)*Premissas!$D$14:$D$20+(Premissas!$D$14:$D$20<=3)*3)+1)/12)+Premissas!$B$42*SUMPRODUCT((Premissas!$D$14:$D$20=2)*Premissas!$C$14:$C$20*Premissas!$B$14:$B$20)*4/3 | Q29: =0+Premissas!$B$42*SUMPRODUCT((Premissas!$D$14:$D$20=3)*Premissas!$C$14:$C$20*Premissas!$B$14:$B$20)*4/3 | R29: =0+Premissas!$B$42*SUMPRODUCT((Premissas!$D$14:$D$20=4)*Premissas!$C$14:$C$20*Premissas!$B$14:$B$20)*4/3 | S29: =0+Premissas!$B$42*SUMPRODUCT((Premissas!$D$14:$D$20=5)*Premissas!$C$14:$C$20*Premissas!$B$14:$B$20)*4/3
A30: Professores (salário + encargos) | B30: 0 | C30: 0 | D30: =D8*Premissas!$B$35 | E30: =E8*Premissas!$B$35 | F30: =F8*Premissas!$B$35 | G30: =G8*Premissas!$B$35 | H30: =H8*Premissas!$B$35 | I30: =I8*Premissas!$B$35 | J30: =J8*Premissas!$B$35 | K30: =K8*Premissas!$B$35 | ... S30: =S8*Premissas!$B$35
A31: Aluguel do espaço | B31: ='Custos mês a mês'!B2 | C31: ='Custos mês a mês'!C2 | D31: ='Custos mês a mês'!D2 | E31: ='Custos mês a mês'!E2 | F31: ='Custos mês a mês'!F2 | G31: ='Custos mês a mês'!G2 | H31: ='Custos mês a mês'!H2 | I31: ='Custos mês a mês'!I2 | ... S31: ='Custos mês a mês'!S2
A32: Água | B32: ='Custos mês a mês'!B3 | C32: ='Custos mês a mês'!C3 | D32: ='Custos mês a mês'!D3 | E32: ='Custos mês a mês'!E3 | F32: ='Custos mês a mês'!F3 | G32: ='Custos mês a mês'!G3 | H32: ='Custos mês a mês'!H3 | I32: ='Custos mês a mês'!I3 | ... S32: ='Custos mês a mês'!S3
A33: Luz | B33: ='Custos mês a mês'!B4 | C33: ='Custos mês a mês'!C4 | D33: ='Custos mês a mês'!D4 | E33: ='Custos mês a mês'!E4 | F33: ='Custos mês a mês'!F4 | G33: ='Custos mês a mês'!G4 | H33: ='Custos mês a mês'!H4 | I33: ='Custos mês a mês'!I4 | ... S33: ='Custos mês a mês'!S4
A34: Telefone | B34: ='Custos mês a mês'!B5 | C34: ='Custos mês a mês'!C5 | D34: ='Custos mês a mês'!D5 | E34: ='Custos mês a mês'!E5 | F34: ='Custos mês a mês'!F5 | G34: ='Custos mês a mês'!G5 | H34: ='Custos mês a mês'!H5 | I34: ='Custos mês a mês'!I5 | ... S34: ='Custos mês a mês'!S5
A35: Internet | B35: ='Custos mês a mês'!B6 | C35: ='Custos mês a mês'!C6 | D35: ='Custos mês a mês'!D6 | E35: ='Custos mês a mês'!E6 | F35: ='Custos mês a mês'!F6 | G35: ='Custos mês a mês'!G6 | H35: ='Custos mês a mês'!H6 | I35: ='Custos mês a mês'!I6 | ... S35: ='Custos mês a mês'!S6
A36: Sistema de gestão DiscoverON | B36: ='Custos mês a mês'!B7 | C36: ='Custos mês a mês'!C7 | D36: ='Custos mês a mês'!D7 | E36: ='Custos mês a mês'!E7 | F36: ='Custos mês a mês'!F7 | G36: ='Custos mês a mês'!G7 | H36: ='Custos mês a mês'!H7 | I36: ='Custos mês a mês'!I7 | ... S36: ='Custos mês a mês'!S7
A37: Itens para aula | B37: ='Custos mês a mês'!B8 | C37: ='Custos mês a mês'!C8 | D37: ='Custos mês a mês'!D8 | E37: ='Custos mês a mês'!E8 | F37: ='Custos mês a mês'!F8 | G37: ='Custos mês a mês'!G8 | H37: ='Custos mês a mês'!H8 | I37: ='Custos mês a mês'!I8 | ... S37: ='Custos mês a mês'!S8
A38: Materiais de limpeza + higiene | B38: ='Custos mês a mês'!B9 | C38: ='Custos mês a mês'!C9 | D38: ='Custos mês a mês'!D9 | E38: ='Custos mês a mês'!E9 | F38: ='Custos mês a mês'!F9 | G38: ='Custos mês a mês'!G9 | H38: ='Custos mês a mês'!H9 | I38: ='Custos mês a mês'!I9 | ... S38: ='Custos mês a mês'!S9
A39: Brindes | B39: ='Custos mês a mês'!B10 | C39: ='Custos mês a mês'!C10 | D39: ='Custos mês a mês'!D10 | E39: ='Custos mês a mês'!E10 | F39: ='Custos mês a mês'!F10 | G39: ='Custos mês a mês'!G10 | H39: ='Custos mês a mês'!H10 | I39: ='Custos mês a mês'!I10 | ... S39: ='Custos mês a mês'!S10
A40: Marketing | B40: ='Custos mês a mês'!B11 | C40: ='Custos mês a mês'!C11 | D40: ='Custos mês a mês'!D11 | E40: ='Custos mês a mês'!E11 | F40: ='Custos mês a mês'!F11 | G40: ='Custos mês a mês'!G11 | H40: ='Custos mês a mês'!H11 | I40: ='Custos mês a mês'!I11 | ... S40: ='Custos mês a mês'!S11
A41: Aluguel dos computadores | B41: ='Custos mês a mês'!B12 | C41: ='Custos mês a mês'!C12 | D41: ='Custos mês a mês'!D12 | E41: ='Custos mês a mês'!E12 | F41: ='Custos mês a mês'!F12 | G41: ='Custos mês a mês'!G12 | H41: ='Custos mês a mês'!H12 | I41: ='Custos mês a mês'!I12 | ... S41: ='Custos mês a mês'!S12
A42: Seguro empresarial | B42: ='Custos mês a mês'!B13 | C42: ='Custos mês a mês'!C13 | D42: ='Custos mês a mês'!D13 | E42: ='Custos mês a mês'!E13 | F42: ='Custos mês a mês'!F13 | G42: ='Custos mês a mês'!G13 | H42: ='Custos mês a mês'!H13 | I42: ='Custos mês a mês'!I13 | ... S42: ='Custos mês a mês'!S13
... A45: Pró-labore | B45: ='Custos mês a mês'!B16 | C45: ='Custos mês a mês'!C16 | D45: ='Custos mês a mês'!D16 | E45: ='Custos mês a mês'!E16 | F45: ='Custos mês a mês'!F16 | G45: ='Custos mês a mês'!G16 | H45: ='Custos mês a mês'!H16 | I45: ='Custos mês a mês'!I16 | ... S45: ='Custos mês a mês'!S16
...

Sheet Cenário Moderado
A1: Cenário Moderado | B1: Out (obras) | C1: Nov (obras) | D1: Dez (M1) | E1: Jan (M2) | F1: Fev (M3) | G1: Mar (M4) | H1: Abr (M5) | I1: Mai (M6) | J1: Jun (M7) | K1: Jul (M8) | L1: Ago (M9) | M1: Set (M10) | N1: Out (M11) | O1: Nov (M12) | P1: Dez (M13) | Q1: Jan (M14) | R1: Fev (M15) | S1: Mar (M16)
A2: Período (0 = out) | B2: 0 | C2: 1 | D2: 2 | E2: 3 | F2: 4 | G2: 5 | H2: 6 | I2: 7 | J2: 8 | K2: 9 | L2: 10 | M2: 11 | N2: 12 | O2: 13 | P2: 14 | Q2: 15 | R2: 16 | S2: 17
A3: Matrículas — entrada manual ✏️ editável | B3: 4 | C3: 35 | D3: 13 | E3: 30 | F3: 30 | G3: 20 | H3: 20 | I3: 20 | J3: 20 | K3: 30 | L3: 30 | M3: 20 | N3: 20 | O3: 30 | P3: 30 | Q3: 20 | R3: 30 | S3: 20 | U3: Break-even (alunos):
A4: Matrículas no período (vale para o cálculo) | B4: =IF(Premissas!$B$59=3,'Canais de aquisição'!C$9,IF(Premissas!$B$59=2,ROUND('Custos mês a mês'!B$11/MAX(Premissas!$B$60,1),0),B3)) | C4: =IF(Premissas!$B$59=3,'Canais de aquisição'!D$9,IF(Premissas!$B$59=2,ROUND('Custos mês a mês'!C$11/MAX(Premissas!$B$60,1),0),C3)) | D4: =IF(Premissas!$B$59=3,'Canais de aquisição'!E$9,IF(Premissas!$B$59=2,ROUND('Custos mês a mês'!D$11/MAX(Premissas!$B$60,1),0),D3)) | E4: =IF(Premissas!$B$59=3,'Canais de aquisição'!F$9,IF(Premissas!$B$59=2,ROUND('Custos mês a mês'!E$11/MAX(Premissas!$B$60,1),0),E3)) | F4: =IF(Premissas!$B$59=3,'Canais de aquisição'!G$9,IF(Premissas!$B$59=2,ROUND('Custos mês a mês'!F$11/MAX(Premissas!$B$60,1),0),F3)) | G4: =IF(Premissas!$B$59=3,'Canais de aquisição'!H$9,IF(Premissas!$B$59=2,ROUND('Custos mês a mês'!G$11/MAX(Premissas!$B$60,1),0),G3)) | H4: =IF(Premissas!$B$59=3,'Canais de aquisição'!I$9,IF(Premissas!$B$59=2,ROUND('Custos mês a mês'!H$11/MAX(Premissas!$B$60,1),0),H3)) | I4: =IF(Premissas!$B$59=3,'Canais de aquisição'!J$9,IF(Premissas!$B$59=2,ROUND('Custos mês a mês'!I$11/MAX(Premissas!$B$60,1),0),I3)) | ... S4: =IF(Premissas!$B$59=3,'Canais de aquisição'!T$9,IF(Premissas!$B$59=2,ROUND('Custos mês a mês'!S$11/MAX(Premissas!$B$60,1),0),S3)) | U4: =Premissas!$B$90
A5: CAC realizado (marketing + canais ÷ matrículas) | B5: =IF(B4=0,0,('Custos mês a mês'!B$11+'Canais de aquisição'!C$10)/B4) | C5: =IF(C4=0,0,('Custos mês a mês'!C$11+'Canais de aquisição'!D$10)/C4) | D5: =IF(D4=0,0,('Custos mês a mês'!D$11+'Canais de aquisição'!E$10)/D4) | E5: =IF(E4=0,0,('Custos mês a mês'!E$11+'Canais de aquisição'!F$10)/E4) | F5: =IF(F4=0,0,('Custos mês a mês'!F$11+'Canais de aquisição'!G$10)/F4) | G5: =IF(G4=0,0,('Custos mês a mês'!G$11+'Canais de aquisição'!H$10)/G4) | H5: =IF(H4=0,0,('Custos mês a mês'!H$11+'Canais de aquisição'!I$10)/H4) | I5: =IF(I4=0,0,('Custos mês a mês'!I$11+'Canais de aquisição'!J$10)/I4) | ... S5: =IF(S4=0,0,('Custos mês a mês'!S$11+'Canais de aquisição'!T$10)/S4)
A6: Desistências no mês | B6: 0 | C6: =B7*Premissas!$B$8*Premissas!$B$55 | D6: =C7*Premissas!$B$8*Premissas!$B$56 | E6: =D7*Premissas!$B$8*Premissas!$B$45 | F6: =E7*Premissas!$B$8*Premissas!$B$46 | G6: =F7*Premissas!$B$8*Premissas!$B$47 | H6: =G7*Premissas!$B$8*Premissas!$B$48 | I6: =H7*Premissas!$B$8*Premissas!$B$49 | J6: =I7*Premissas!$B$8*Premissas!$B$50 | K6: =J7*Premissas!$B$8*Premissas!$B$51 | L6: =K7*Premissas!$B$8*Premissas!$B$52 | M6: =L7*Premissas!$B$8*Premissas!$B$53 | N6: =M7*Premissas!$B$8*Premissas!$B$54 | O6: =N7*Premissas!$B$8*Premissas!$B$55 | P6: =O7*Premissas!$B$8*Premissas!$B$56 | Q6: =P7*Premissas!$B$8*Premissas!$B$45 | R6: =Q7*Premissas!$B$8*Premissas!$B$46 | S6: =R7*Premissas!$B$8*Premissas!$B$47 | U6: 🟢 VERDE FORTE = mês do BREAK-EVEN
A7: Total de alunos | B7: =B4 | C7: =B7-C6+C4 | D7: =C7-D6+D4 | E7: =D7-E6+E4 | F7: =E7-F6+F4 | G7: =F7-G6+G4 | H7: =G7-H6+H4 | I7: =H7-I6+I4 | J7: =I7-J6+J4 | ... S7: =R7-S6+S4 | U7: 🟦 AZUL = mês do PAYBACK
A8: Professores necessários | B8: 0 | C8: 0 | D8: =CEILING(CEILING(D7*Premissas!$B$37/Premissas!$B$27,1)*Premissas!$B$28/Premissas!$B$34,1)+CEILING(CEILING(D7*Premissas!$B$38/Premissas!$B$30,1)*Premissas!$B$31/Premissas!$B$34,1) | E8: =CEILING(CEILING(E7*Premissas!$B$37/Premissas!$B$27,1)*Premissas!$B$28/Premissas!$B$34,1)+CEILING(CEILING(E7*Premissas!$B$38/Premissas!$B$30,1)*Premissas!$B$31/Premissas!$B$34,1) | F8: =CEILING(CEILING(F7*Premissas!$B$37/Premissas!$B$27,1)*Premissas!$B$28/Premissas!$B$34,1)+CEILING(CEILING(F7*Premissas!$B$38/Premissas!$B$30,1)*Premissas!$B$31/Premissas!$B$34,1) | G8: =CEILING(CEILING(G7*Premissas!$B$37/Premissas!$B$27,1)*Premissas!$B$28/Premissas!$B$34,1)+CEILING(CEILING(G7*Premissas!$B$38/Premissas!$B$30,1)*Premissas!$B$31/Premissas!$B$34,1) | H8: =CEILING(CEILING(H7*Premissas!$B$37/Premissas!$B$27,1)*Premissas!$B$28/Premissas!$B$34,1)+CEILING(CEILING(H7*Premissas!$B$38/Premissas!$B$30,1)*Premissas!$B$31/Premissas!$B$34,1) | I8: =CEILING(CEILING(I7*Premissas!$B$37/Premissas!$B$27,1)*Premissas!$B$28/Premissas!$B$34,1)+CEILING(CEILING(I7*Premissas!$B$38/Premissas!$B$30,1)*Premissas!$B$31/Premissas!$B$34,1) | J8: =CEILING(CEILING(J7*Premissas!$B$37/Premissas!$B$27,1)*Premissas!$B$28/Premissas!$B$34,1)+CEILING(CEILING(J7*Premissas!$B$38/Premissas!$B$30,1)*Premissas!$B$31/Premissas!$B$34,1) | K8: =CEILING(CEILING(K7*Premissas!$B$37/Premissas!$B$27,1)*Premissas!$B$28/Premissas!$B$34,1)+CEILING(CEILING(K7*Premissas!$B$38/Premissas!$B$30,1)*Premissas!$B$31/Premissas!$B$34,1) | ... S8: =CEILING(CEILING(S7*Premissas!$B$37/Premissas!$B$27,1)*Premissas!$B$28/Premissas!$B$34,1)+CEILING(CEILING(S7*Premissas!$B$38/Premissas!$B$30,1)*Premissas!$B$31/Premissas!$B$34,1) | U8: 🟩 verde claro = meses já positivos
A9: Ocupação das salas (100% = grade cheia) | B9: 0 | C9: 0 | D9: =MAX(CEILING(D7*Premissas!$B$37/Premissas!$B$27,1)*Premissas!$B$28/(Premissas!$B$26*Premissas!$B$32*Premissas!$B$33*Premissas!$B$25),CEILING(D7*Premissas!$B$38/Premissas!$B$30,1)*Premissas!$B$31/(Premissas!$B$29*Premissas!$B$32*Premissas!$B$33*Premissas!$B$25)) | E9: =MAX(CEILING(E7*Premissas!$B$37/Premissas!$B$27,1)*Premissas!$B$28/(Premissas!$B$26*Premissas!$B$32*Premissas!$B$33*Premissas!$B$25),CEILING(E7*Premissas!$B$38/Premissas!$B$30,1)*Premissas!$B$31/(Premissas!$B$29*Premissas!$B$32*Premissas!$B$33*Premissas!$B$25)) | F9: =MAX(CEILING(F7*Premissas!$B$37/Premissas!$B$27,1)*Premissas!$B$28/(Premissas!$B$26*Premissas!$B$32*Premissas!$B$33*Premissas!$B$25),CEILING(F7*Premissas!$B$38/Premissas!$B$30,1)*Premissas!$B$31/(Premissas!$B$29*Premissas!$B$32*Premissas!$B$33*Premissas!$B$25)) | G9: =MAX(CEILING(G7*Premissas!$B$37/Premissas!$B$27,1)*Premissas!$B$28/(Premissas!$B$26*Premissas!$B$32*Premissas!$B$33*Premissas!$B$25),CEILING(G7*Premissas!$B$38/Premissas!$B$30,1)*Premissas!$B$31/(Premissas!$B$29*Premissas!$B$32*Premissas!$B$33*Premissas!$B$25)) | H9: =MAX(CEILING(H7*Premissas!$B$37/Premissas!$B$27,1)*Premissas!$B$28/(Premissas!$B$26*Premissas!$B$32*Premissas!$B$33*Premissas!$B$25),CEILING(H7*Premissas!$B$38/Premissas!$B$30,1)*Premissas!$B$31/(Premissas!$B$29*Premissas!$B$32*Premissas!$B$33*Premissas!$B$25)) | I9: =MAX(CEILING(I7*Premissas!$B$37/Premissas!$B$27,1)*Premissas!$B$28/(Premissas!$B$26*Premissas!$B$32*Premissas!$B$33*Premissas!$B$25),CEILING(I7*Premissas!$B$38/Premissas!$B$30,1)*Premissas!$B$31/(Premissas!$B$29*Premissas!$B$32*Premissas!$B$33*Premissas!$B$25)) | J9: =MAX(CEILING(J7*Premissas!$B$37/Premissas!$B$27,1)*Premissas!$B$28/(Premissas!$B$26*Premissas!$B$32*Premissas!$B$33*Premissas!$B$25),CEILING(J7*Premissas!$B$38/Premissas!$B$30,1)*Premissas!$B$31/(Premissas!$B$29*Premissas!$B$32*Premissas!$B$33*Premissas!$B$25)) | K9: =MAX(CEILING(K7*Premissas!$B$37/Premissas!$B$27,1)*Premissas!$B$28/(Premissas!$B$26*Premissas!$B$32*Premissas!$B$33*Premissas!$B$25),CEILING(K7*Premissas!$B$38/Premissas!$B$30,1)*Premissas!$B$31/(Premissas!$B$29*Premissas!$B$32*Premissas!$B$33*Premissas!$B$25)) | ... S9: =MAX(CEILING(S7*Premissas!$B$37/Premissas!$B$27,1)*Premissas!$B$28/(Premissas!$B$26*Premissas!$B$32*Premissas!$B$33*Premissas!$B$25),CEILING(S7*Premissas!$B$38/Premissas!$B$30,1)*Premissas!$B$31/(Premissas!$B$29*Premissas!$B$32*Premissas!$B$33*Premissas!$B$25))
A11: RECEITA RECEBIDA (caixa)
A12: Matrícula | B12: =B4*Premissas!$B$3 | C12: =C4*Premissas!$B$3 | D12: =D4*Premissas!$B$3 | E12: =E4*Premissas!$B$3 | F12: =F4*Premissas!$B$3 | G12: =G4*Premissas!$B$3 | H12: =H4*Premissas!$B$3 | I12: =I4*Premissas!$B$3 | ... S12: =S4*Premissas!$B$3
A13: Mensalidade recebida (líq. de inadimplência) | B13: 0 | C13: 0 | D13: =C7*Premissas!$B$2*(1-Premissas!$B$9) | E13: =D7*Premissas!$B$2*(1-Premissas!$B$9) | F13: =E7*Premissas!$B$2*(1-Premissas!$B$9) | G13: =F7*Premissas!$B$2*(1-Premissas!$B$9) | H13: =G7*Premissas!$B$2*(1-Premissas!$B$9) | I13: =H7*Premissas!$B$2*(1-Premissas!$B$9) | J13: =I7*Premissas!$B$2*(1-Premissas!$B$9) | K13: =J7*Premissas!$B$2*(1-Premissas!$B$9) | ... S13: =R7*Premissas!$B$2*(1-Premissas!$B$9)
A14: Material antecipado no cartão | B14: =B4*Premissas!$B$5 | C14: =C4*Premissas!$B$5 | D14: =D4*Premissas!$B$5 | E14: =E4*Premissas!$B$5 | F14: =F4*Premissas!$B$5 | G14: =G4*Premissas!$B$5 | H14: =H4*Premissas!$B$5 | I14: =I4*Premissas!$B$5 | ... S14: =S4*Premissas!$B$5
A15: Receita recebida | B15: =SUM(B12:B14) | C15: =SUM(C12:C14) | D15: =SUM(D12:D14) | E15: =SUM(E12:E14) | F15: =SUM(F12:F14) | G15: =SUM(G12:G14) | H15: =SUM(H12:H14) | I15: =SUM(I12:I14) | ... S15: =SUM(S12:S14)
A17: BASE DO SIMPLES NACIONAL
A18: Faturamento do mês (nota emitida) | B18: =B4*Premissas!$B$3+B4*Premissas!$B$4 | C18: =C4*Premissas!$B$3+C4*Premissas!$B$4 | D18: =D4*Premissas!$B$3+C7*Premissas!$B$2+D4*Premissas!$B$4 | E18: =E4*Premissas!$B$3+D7*Premissas!$B$2+E4*Premissas!$B$4 | F18: =F4*Premissas!$B$3+E7*Premissas!$B$2+F4*Premissas!$B$4 | G18: =G4*Premissas!$B$3+F7*Premissas!$B$2+G4*Premissas!$B$4 | H18: =H4*Premissas!$B$3+G7*Premissas!$B$2+H4*Premissas!$B$4 | I18: =I4*Premissas!$B$3+H7*Premissas!$B$2+I4*Premissas!$B$4 | J18: =J4*Premissas!$B$3+I7*Premissas!$B$2+J4*Premissas!$B$4 | K18: =K4*Premissas!$B$3+J7*Premissas!$B$2+K4*Premissas!$B$4 | ... S18: =S4*Premissas!$B$3+R7*Premissas!$B$2+S4*Premissas!$B$4
A19: RBT12 proporcionalizado | B19: =SUM($B$18:B18)/1*12 | C19: =SUM($B$18:C18)/2*12 | D19: =SUM($B$18:D18)/3*12 | E19: =SUM($B$18:E18)/4*12 | F19: =SUM($B$18:F18)/5*12 | G19: =SUM($B$18:G18)/6*12 | H19: =SUM($B$18:H18)/7*12 | I19: =SUM($B$18:I18)/8*12 | J19: =SUM($B$18:J18)/9*12 | K19: =SUM($B$18:K18)/10*12 | L19: =SUM($B$18:L18)/11*12 | M19: =SUM(B18:M18) | N19: =SUM(C18:N18) | O19: =SUM(D18:O18) | P19: =SUM(E18:P18) | Q19: =SUM(F18:Q18) | R19: =SUM(G18:R18) | S19: =SUM(H18:S18)
A20: Alíquota efetiva do Simples | B20: =IF(B19=0,Premissas!$C$66,IF(B19<=Premissas!$B$66,(B19*Premissas!$C$66-Premissas!$D$66)/B19,IF(B19<=Premissas!$B$67,(B19*Premissas!$C$67-Premissas!$D$67)/B19,IF(B19<=Premissas!$B$68,(B19*Premissas!$C$68-Premissas!$D$68)/B19,IF(B19<=Premissas!$B$69,(B19*Premissas!$C$69-Premissas!$D$69)/B19,IF(B19<=Premissas!$B$70,(B19*Premissas!$C$70-Premissas!$D$70)/B19,(B19*Premissas!$C$71-Premissas!$D$71)/B19)))))) | C20: =IF(C19=0,Premissas!$C$66,IF(C19<=Premissas!$B$66,(C19*Premissas!$C$66-Premissas!$D$66)/C19,IF(C19<=Premissas!$B$67,(C19*Premissas!$C$67-Premissas!$D$67)/C19,IF(C19<=Premissas!$B$68,(C19*Premissas!$C$68-Premissas!$D$68)/C19,IF(C19<=Premissas!$B$69,(C19*Premissas!$C$69-Premissas!$D$69)/C19,IF(C19<=Premissas!$B$70,(C19*Premissas!$C$70-Premissas!$D$70)/C19,(C19*Premissas!$C$71-Premissas!$D$71)/C19)))))) | D20: =IF(D19=0,Premissas!$C$66,IF(D19<=Premissas!$B$66,(D19*Premissas!$C$66-Premissas!$D$66)/D19,IF(D19<=Premissas!$B$67,(D19*Premissas!$C$67-Premissas!$D$67)/D19,IF(D19<=Premissas!$B$68,(D19*Premissas!$C$68-Premissas!$D$68)/D19,IF(D19<=Premissas!$B$69,(D19*Premissas!$C$69-Premissas!$D$69)/D19,IF(D19<=Premissas!$B$70,(D19*Premissas!$C$70-Premissas!$D$70)/D19,(D19*Premissas!$C$71-Premissas!$D$71)/D19)))))) | E20: =IF(E19=0,Premissas!$C$66,IF(E19<=Premissas!$B$66,(E19*Premissas!$C$66-Premissas!$D$66)/E19,IF(E19<=Premissas!$B$67,(E19*Premissas!$C$67-Premissas!$D$67)/E19,IF(E19<=Premissas!$B$68,(E19*Premissas!$C$68-Premissas!$D$68)/E19,IF(E19<=Premissas!$B$69,(E19*Premissas!$C$69-Premissas!$D$69)/E19,IF(E19<=Premissas!$B$70,(E19*Premissas!$C$70-Premissas!$D$70)/E19,(E19*Premissas!$C$71-Premissas!$D$71)/E19)))))) | F20: =IF(F19=0,Premissas!$C$66,IF(F19<=Premissas!$B$66,(F19*Premissas!$C$66-Premissas!$D$66)/F19,IF(F19<=Premissas!$B$67,(F19*Premissas!$C$67-Premissas!$D$67)/F19,IF(F19<=Premissas!$B$68,(F19*Premissas!$C$68-Premissas!$D$68)/F19,IF(F19<=Premissas!$B$69,(F19*Premissas!$C$69-Premissas!$D$69)/F19,IF(F19<=Premissas!$B$70,(F19*Premissas!$C$70-Premissas!$D$70)/F19,(F19*Premissas!$C$71-Premissas!$D$71)/F19)))))) | G20: =IF(G19=0,Premissas!$C$66,IF(G19<=Premissas!$B$66,(G19*Premissas!$C$66-Premissas!$D$66)/G19,IF(G19<=Premissas!$B$67,(G19*Premissas!$C$67-Premissas!$D$67)/G19,IF(G19<=Premissas!$B$68,(G19*Premissas!$C$68-Premissas!$D$68)/G19,IF(G19<=Premissas!$B$69,(G19*Premissas!$C$69-Premissas!$D$69)/G19,IF(G19<=Premissas!$B$70,(G19*Premissas!$C$70-Premissas!$D$70)/G19,(G19*Premissas!$C$71-Premissas!$D$71)/G19)))))) | H20: =IF(H19=0,Premissas!$C$66,IF(H19<=Premissas!$B$66,(H19*Premissas!$C$66-Premissas!$D$66)/H19,IF(H19<=Premissas!$B$67,(H19*Premissas!$C$67-Premissas!$D$67)/H19,IF(H19<=Premissas!$B$68,(H19*Premissas!$C$68-Premissas!$D$68)/H19,IF(H19<=Premissas!$B$69,(H19*Premissas!$C$69-Premissas!$D$69)/H19,IF(H19<=Premissas!$B$70,(H19*Premissas!$C$70-Premissas!$D$70)/H19,(H19*Premissas!$C$71-Premissas!$D$71)/H19)))))) | I20: =IF(I19=0,Premissas!$C$66,IF(I19<=Premissas!$B$66,(I19*Premissas!$C$66-Premissas!$D$66)/I19,IF(I19<=Premissas!$B$67,(I19*Premissas!$C$67-Premissas!$D$67)/I19,IF(I19<=Premissas!$B$68,(I19*Premissas!$C$68-Premissas!$D$68)/I19,IF(I19<=Premissas!$B$69,(I19*Premissas!$C$69-Premissas!$D$69)/I19,IF(I19<=Premissas!$B$70,(I19*Premissas!$C$70-Premissas!$D$70)/I19,(I19*Premissas!$C$71-Premissas!$D$71)/I19)))))) | ... S20: =IF(S19=0,Premissas!$C$66,IF(S19<=Premissas!$B$66,(S19*Premissas!$C$66-Premissas!$D$66)/S19,IF(S19<=Premissas!$B$67,(S19*Premissas!$C$67-Premissas!$D$67)/S19,IF(S19<=Premissas!$B$68,(S19*Premissas!$C$68-Premissas!$D$68)/S19,IF(S19<=Premissas!$B$69,(S19*Premissas!$C$69-Premissas!$D$69)/S19,IF(S19<=Premissas!$B$70,(S19*Premissas!$C$70-Premissas!$D$70)/S19,(S19*Premissas!$C$71-Premissas!$D$71)/S19))))))
A22: DESPESAS
A23: Impostos (Simples progressivo) | B23: =B18*B20 | C23: =C18*C20 | D23: =D18*D20 | E23: =E18*E20 | F23: =F18*F20 | G23: =G18*G20 | H23: =H18*H20 | I23: =I18*I20 | ... S23: =S18*S20
A24: Material — parcelas 12x | B24: 0 | C24: 0 | D24: =SUM($B$4:D4)*Premissas!$B$6/12 | E24: =SUM($B$4:E4)*Premissas!$B$6/12 | F24: =SUM($B$4:F4)*Premissas!$B$6/12 | G24: =SUM($B$4:G4)*Premissas!$B$6/12 | H24: =SUM($B$4:H4)*Premissas!$B$6/12 | I24: =SUM($B$4:I4)*Premissas!$B$6/12 | J24: =SUM($B$4:J4)*Premissas!$B$6/12 | K24: =SUM($B$4:K4)*Premissas!$B$6/12 | ... O24: =SUM($B$4:O4)*Premissas!$B$6/12 | P24: =SUM(E4:P4)*Premissas!$B$6/12 | Q24: =SUM(F4:Q4)*Premissas!$B$6/12 | R24: =SUM(G4:R4)*Premissas!$B$6/12 | S24: =SUM(H4:S4)*Premissas!$B$6/12
A25: Comissão do vendedor | B25: =IF(B2>=Premissas!$D$14,B4*Premissas!$B$10*(1+Premissas!$B$11),0) | C25: =IF(C2>=Premissas!$D$14,C4*Premissas!$B$10*(1+Premissas!$B$11),0) | D25: =IF(D2>=Premissas!$D$14,D4*Premissas!$B$10*(1+Premissas!$B$11),0) | E25: =IF(E2>=Premissas!$D$14,E4*Premissas!$B$10*(1+Premissas!$B$11),0) | F25: =IF(F2>=Premissas!$D$14,F4*Premissas!$B$10*(1+Premissas!$B$11),0) | G25: =IF(G2>=Premissas!$D$14,G4*Premissas!$B$10*(1+Premissas!$B$11),0) | H25: =IF(H2>=Premissas!$D$14,H4*Premissas!$B$10*(1+Premissas!$B$11),0) | I25: =IF(I2>=Premissas!$D$14,I4*Premissas!$B$10*(1+Premissas!$B$11),0) | ... S25: =IF(S2>=Premissas!$D$14,S4*Premissas!$B$10*(1+Premissas!$B$11),0)
A26: Aquisição de alunos (custo dos canais) | B26: ='Canais de aquisição'!C$10 | C26: ='Canais de aquisição'!D$10 | D26: ='Canais de aquisição'!E$10 | E26: ='Canais de aquisição'!F$10 | F26: ='Canais de aquisição'!G$10 | G26: ='Canais de aquisição'!H$10 | H26: ='Canais de aquisição'!I$10 | I26: ='Canais de aquisição'!J$10 | ... S26: ='Canais de aquisição'!T$10
A27: Folha + encargos mensais (só quem já entrou) | B27: =SUMPRODUCT((Premissas!$D$14:$D$20<=B2)*Premissas!$B$14:$B$20*(1+Premissas!$C$14:$C$20*Premissas!$B$11)) | C27: =SUMPRODUCT((Premissas!$D$14:$D$20<=C2)*Premissas!$B$14:$B$20*(1+Premissas!$C$14:$C$20*Premissas!$B$11)) | D27: =SUMPRODUCT((Premissas!$D$14:$D$20<=D2)*Premissas!$B$14:$B$20*(1+Premissas!$C$14:$C$20*Premissas!$B$11)) | E27: =SUMPRODUCT((Premissas!$D$14:$D$20<=E2)*Premissas!$B$14:$B$20*(1+Premissas!$C$14:$C$20*Premissas!$B$11)) | F27: =SUMPRODUCT((Premissas!$D$14:$D$20<=F2)*Premissas!$B$14:$B$20*(1+Premissas!$C$14:$C$20*Premissas!$B$11)) | G27: =SUMPRODUCT((Premissas!$D$14:$D$20<=G2)*Premissas!$B$14:$B$20*(1+Premissas!$C$14:$C$20*Premissas!$B$11)) | H27: =SUMPRODUCT((Premissas!$D$14:$D$20<=H2)*Premissas!$B$14:$B$20*(1+Premissas!$C$14:$C$20*Premissas!$B$11)) | I27: =SUMPRODUCT((Premissas!$D$14:$D$20<=I2)*Premissas!$B$14:$B$20*(1+Premissas!$C$14:$C$20*Premissas!$B$11)) | ... S27: =SUMPRODUCT((Premissas!$D$14:$D$20<=S2)*Premissas!$B$14:$B$20*(1+Premissas!$C$14:$C$20*Premissas!$B$11))
A28: Vale-transporte / benefícios | B28: =SUMPRODUCT((Premissas!$D$14:$D$20<=B2)*Premissas!$C$14:$C$20*(Premissas!$B$14:$B$20>0))*Premissas!$B$12 | C28: =SUMPRODUCT((Premissas!$D$14:$D$20<=C2)*Premissas!$C$14:$C$20*(Premissas!$B$14:$B$20>0))*Premissas!$B$12 | D28: =SUMPRODUCT((Premissas!$D$14:$D$20<=D2)*Premissas!$C$14:$C$20*(Premissas!$B$14:$B$20>0))*Premissas!$B$12 | E28: =SUMPRODUCT((Premissas!$D$14:$D$20<=E2)*Premissas!$C$14:$C$20*(Premissas!$B$14:$B$20>0))*Premissas!$B$12 | F28: =SUMPRODUCT((Premissas!$D$14:$D$20<=F2)*Premissas!$C$14:$C$20*(Premissas!$B$14:$B$20>0))*Premissas!$B$12 | G28: =SUMPRODUCT((Premissas!$D$14:$D$20<=G2)*Premissas!$C$14:$C$20*(Premissas!$B$14:$B$20>0))*Premissas!$B$12 | H28: =SUMPRODUCT((Premissas!$D$14:$D$20<=H2)*Premissas!$C$14:$C$20*(Premissas!$B$14:$B$20>0))*Premissas!$B$12 | I28: =SUMPRODUCT((Premissas!$D$14:$D$20<=I2)*Premissas!$C$14:$C$20*(Premissas!$B$14:$B$20>0))*Premissas!$B$12 | ... S28: =SUMPRODUCT((Premissas!$D$14:$D$20<=S2)*Premissas!$C$14:$C$20*(Premissas!$B$14:$B$20>0))*Premissas!$B$12
A29: 13º e férias (desembolso) | B29: 0 | C29: 0 | D29: =Premissas!$B$41*SUMPRODUCT((Premissas!$D$14:$D$20<=2)*Premissas!$C$14:$C$20*Premissas!$B$14:$B$20*(2-((Premissas!$D$14:$D$20>0)*Premissas!$D$14:$D$20+(Premissas!$D$14:$D$20<=0)*0)+1)/12)+0 | E29: 0 | F29: 0 | G29: 0 | H29: 0 | I29: 0 | J29: 0 | K29: 0 | L29: 0 | M29: 0 | N29: =0+Premissas!$B$42*SUMPRODUCT((Premissas!$D$14:$D$20=0)*Premissas!$C$14:$C$20*Premissas!$B$14:$B$20)*4/3 | O29: =0+Premissas!$B$42*SUMPRODUCT((Premissas!$D$14:$D$20=1)*Premissas!$C$14:$C$20*Premissas!$B$14:$B$20)*4/3 | P29: =Premissas!$B$41*SUMPRODUCT((Premissas!$D$14:$D$20<=14)*Premissas!$C$14:$C$20*Premissas!$B$14:$B$20*(14-((Premissas!$D$14:$D$20>3)*Premissas!$D$14:$D$20+(Premissas!$D$14:$D$20<=3)*3)+1)/12)+Premissas!$B$42*SUMPRODUCT((Premissas!$D$14:$D$20=2)*Premissas!$C$14:$C$20*Premissas!$B$14:$B$20)*4/3 | Q29: =0+Premissas!$B$42*SUMPRODUCT((Premissas!$D$14:$D$20=3)*Premissas!$C$14:$C$20*Premissas!$B$14:$B$20)*4/3 | R29: =0+Premissas!$B$42*SUMPRODUCT((Premissas!$D$14:$D$20=4)*Premissas!$C$14:$C$20*Premissas!$B$14:$B$20)*4/3 | S29: =0+Premissas!$B$42*SUMPRODUCT((Premissas!$D$14:$D$20=5)*Premissas!$C$14:$C$20*Premissas!$B$14:$B$20)*4/3
A30: Professores (salário + encargos) | B30: 0 | C30: 0 | D30: =D8*Premissas!$B$35 | E30: =E8*Premissas!$B$35 | F30: =F8*Premissas!$B$35 | G30: =G8*Premissas!$B$35 | H30: =H8*Premissas!$B$35 | I30: =I8*Premissas!$B$35 | J30: =J8*Premissas!$B$35 | K30: =K8*Premissas!$B$35 | ... S30: =S8*Premissas!$B$35
A31: Aluguel do espaço | B31: ='Custos mês a mês'!B2 | C31: ='Custos mês a mês'!C2 | D31: ='Custos mês a mês'!D2 | E31: ='Custos mês a mês'!E2 | F31: ='Custos mês a mês'!F2 | G31: ='Custos mês a mês'!G2 | H31: ='Custos mês a mês'!H2 | I31: ='Custos mês a mês'!I2 | ... S31: ='Custos mês a mês'!S2
A32: Água | B32: ='Custos mês a mês'!B3 | C32: ='Custos mês a mês'!C3 | D32: ='Custos mês a mês'!D3 | E32: ='Custos mês a mês'!E3 | F32: ='Custos mês a mês'!F3 | G32: ='Custos mês a mês'!G3 | H32: ='Custos mês a mês'!H3 | I32: ='Custos mês a mês'!I3 | ... S32: ='Custos mês a mês'!S3
A33: Luz | B33: ='Custos mês a mês'!B4 | C33: ='Custos mês a mês'!C4 | D33: ='Custos mês a mês'!D4 | E33: ='Custos mês a mês'!E4 | F33: ='Custos mês a mês'!F4 | G33: ='Custos mês a mês'!G4 | H33: ='Custos mês a mês'!H4 | I33: ='Custos mês a mês'!I4 | ... S33: ='Custos mês a mês'!S4
A34: Telefone | B34: ='Custos mês a mês'!B5 | C34: ='Custos mês a mês'!C5 | D34: ='Custos mês a mês'!D5 | E34: ='Custos mês a mês'!E5 | F34: ='Custos mês a mês'!F5 | G34: ='Custos mês a mês'!G5 | H34: ='Custos mês a mês'!H5 | I34: ='Custos mês a mês'!I5 | ... S34: ='Custos mês a mês'!S5
A35: Internet | B35: ='Custos mês a mês'!B6 | C35: ='Custos mês a mês'!C6 | D35: ='Custos mês a mês'!D6 | E35: ='Custos mês a mês'!E6 | F35: ='Custos mês a mês'!F6 | G35: ='Custos mês a mês'!G6 | H35: ='Custos mês a mês'!H6 | I35: ='Custos mês a mês'!I6 | ... S35: ='Custos mês a mês'!S6
A36: Sistema de gestão DiscoverON | B36: ='Custos mês a mês'!B7 | C36: ='Custos mês a mês'!C7 | D36: ='Custos mês a mês'!D7 | E36: ='Custos mês a mês'!E7 | F36: ='Custos mês a mês'!F7 | G36: ='Custos mês a mês'!G7 | H36: ='Custos mês a mês'!H7 | I36: ='Custos mês a mês'!I7 | ... S36: ='Custos mês a mês'!S7
A37: Itens para aula | B37: ='Custos mês a mês'!B8 | C37: ='Custos mês a mês'!C8 | D37: ='Custos mês a mês'!D8 | E37: ='Custos mês a mês'!E8 | F37: ='Custos mês a mês'!F8 | G37: ='Custos mês a mês'!G8 | H37: ='Custos mês a mês'!H8 | I37: ='Custos mês a mês'!I8 | ... S37: ='Custos mês a mês'!S8
A38: Materiais de limpeza + higiene | B38: ='Custos mês a mês'!B9 | C38: ='Custos mês a mês'!C9 | D38: ='Custos mês a mês'!D9 | E38: ='Custos mês a mês'!E9 | F38: ='Custos mês a mês'!F9 | G38: ='Custos mês a mês'!G9 | H38: ='Custos mês a mês'!H9 | I38: ='Custos mês a mês'!I9 | ... S38: ='Custos mês a mês'!S9
A39: Brindes | B39: ='Custos mês a mês'!B10 | C39: ='Custos mês a mês'!C10 | D39: ='Custos mês a mês'!D10 | E39: ='Custos mês a mês'!E10 | F39: ='Custos mês a mês'!F10 | G39: ='Custos mês a mês'!G10 | H39: ='Custos mês a mês'!H10 | I39: ='Custos mês a mês'!I10 | ... S39: ='Custos mês a mês'!S10
A40: Marketing | B40: ='Custos mês a mês'!B11 | C40: ='Custos mês a mês'!C11 | D40: ='Custos mês a mês'!D11 | E40: ='Custos mês a mês'!E11 | F40: ='Custos mês a mês'!F11 | G40: ='Custos mês a mês'!G11 | H40: ='Custos mês a mês'!H11 | I40: ='Custos mês a mês'!I11 | ... S40: ='Custos mês a mês'!S11
A41: Aluguel dos computadores | B41: ='Custos mês a mês'!B12 | C41: ='Custos mês a mês'!C12 | D41: ='Custos mês a mês'!D12 | E41: ='Custos mês a mês'!E12 | F41: ='Custos mês a mês'!F12 | G41: ='Custos mês a mês'!G12 | H41: ='Custos mês a mês'!H12 | I41: ='Custos mês a mês'!I12 | ... S41: ='Custos mês a mês'!S12
A42: Seguro empresarial | B42: ='Custos mês a mês'!B13 | C42: ='Custos mês a mês'!C13 | D42: ='Custos mês a mês'!D13 | E42: ='Custos mês a mês'!E13 | F42: ='Custos mês a mês'!F13 | G42: ='Custos mês a mês'!G13 | H42: ='Custos mês a mês'!H13 | I42: ='Custos mês a mês'!I13 | ... S42: ='Custos mês a mês'!S13
